Workbook

Sheet Bem Casado
A1: FICHA TÉCNICA
A3: Produto: | B3: Bem casado | E3: Rendimento: | F3: 15 | H3: Tempo de preparo (min) | J3: 120
A5: Item | D5: Quant. Insumo | E5: Valo do insumo | F5: Quant. Utilizada | G5: Valor custo
A6: ovo | D6: 3000 | E6: 40 | F6: 150 | G6: =(F6*E6)/D6 -> 2 | I6: Metodologia Hora Trabalhada
A7: açucar | D7: 1000 | E7: 4.5 | F7: 95 | G7: =(F7*E7)/D7 -> 0.4275 | I7: Custo fixo (R$/min) | K7: 0.02
A8: farinha | D8: 1000 | E8: 4.5 | F8: 45 | G8: =(F8*E8)/D8 -> 0.2025 | I8: Mão de obra ($/min) | K8: =Custos!L15 -> 0.09469697
A9: fécula de batata | D9: 1000 | E9: 15 | F9: 45 | G9: =(F9*E9)/D9 -> 0.675
A10: fermento | D10: 250 | E10: 8 | F10: 7 | G10: =(F10*E10)/D10 -> 0.224 | I10: Custo total dos produto
A11: agua | D11: 1000 | E11: 1 | F11: 15 | G11: =(F11*E11)/D11 -> 0.015 | I11: custo fixo | L11: =K7*J3 -> 2.4
A12: baunilha | D12: 15 | E12: 3 | F12: 2 | G12: =(F12*E12)/D12 -> 0.4 | I12: custo variável | L12: =G18 -> 22.544
A13: açucar impalpavel | D13: 1000 | E13: 16 | F13: 100 | G13: =(F13*E13)/D13 -> 1.6 | I13: mão de obra | L13: =K8*J3 -> 11.363636
A14: doce de leite | D14: 1000 | E14: 30 | F14: 400 | G14: =(F14*E14)/D14 -> 12 | I14: Custo total | L14: =SUM(L11:L13) -> 36.307636
A15: embalagem | D15: 40 | E15: 10 | F15: 20 | G15: =(F15*E15)/D15 -> 5 | I15: Lucro 30% | L15: =L14*0.5 -> 18.153818
D16: 1 | E16: 0 | F16: 0 | G16: =(F16*E16)/D16 -> 0 | I16: Valor ideal de venda | L16: =SUM(L14:L15) -> 54.461455
D17: 1 | E17: 0 | F17: 0 | G17: =(F17*E17)/D17 -> 0 | I17: VENDA
E18: Custo total de matéria-prima | G18: =SUM(G6:G17) -> 22.544
G22: =O31/F3 -> 3.6738424
L25: Lucro 30% | O25: =L14*0.3 -> 10.892291
L26: Lucro 50% | O26: =18.8*0.5 -> 9.4
L27: Lucro 100% | O27: =18.8*1 -> 18.8
L29: Valor ideal de venda (30%) | O29: =L14+L15 -> 54.461455
L30: Valor ideal de venda (50%) | O30: =L14+O26 -> 45.707636
L31: Valor ideal de venda (100%) | O31: =L14+O27 -> 55.107636

Sheet cesta  Personalizada
A1: FICHA TÉCNICA
A3: Produto: | B3: cesta personalizada | E3: Rendimento: | F3: 1 | H3: Tempo de preparo (min) | J3: 120
A5: Item | D5: Quant. Insumo | E5: Valo do insumo | F5: Quant. Utilizada | G5: Valor custo
A6: cesta | D6: 1 | E6: 30 | F6: 1 | G6: =(F6*E6)/D6 -> 30 | I6: Metodologia Hora Trabalhada
A7: saco | D7: 1 | E7: 4 | F7: 1 | G7: =(F7*E7)/D7 -> 4 | I7: Custo fixo ($/min) | K7: =Custos!F15 -> 0.022037037
A8: balão | D8: 1 | E8: 31.7 | F8: 1 | G8: =(F8*E8)/D8 -> 31.7 | I8: Mão de obra ($/min) | K8: =Custos!L15 -> 0.09469697
A9: trufas | D9: 1 | E9: 3.5 | F9: 15 | G9: =(F9*E9)/D9 -> 52.5
A10: pão de mel | D10: 1 | E10: 5 | F10: 7 | G10: =(F10*E10)/D10 -> 35 | I10: Custo total dos produto
A11: mini bolo | D11: 1 | E11: 18 | F11: 1 | G11: =(F11*E11)/D11 -> 18 | I11: custo fixo | L11: =K7*J3 -> 2.6444444
A12: etiquetas | D12: 1000 | E12: 100 | F12: 3 | G12: =(F12*E12)/D12 -> 0.3 | I12: custo variável | L12: =G18 -> 191.5
A13: papel Arroz | D13: 1 | E13: 20 | F13: 1 | G13: =(F13*E13)/D13 -> 20 | I13: mão de obra | L13: =K8*J3 -> 11.363636
I14: Custo total | L14: =SUM(L11:L13) -> 205.50808
I15: Lucro 30% | L15: =L14*0.3 -> 61.652424
I16: Lucro 50% | L16: =L14*0.5 -> 102.75404
I17: Lucro 100% | L17: =L14*1 -> 205.50808
E18: Custo total de matéria-prima | G18: =SUM(G6:G17) -> 191.5
E19: Custo por grama | G19: =(F19*E19)/D19 -> #VALUE! | I19: Valor ideal de venda (30%) | L19: =L14+L15 -> 267.16051
I20: Valor ideal de venda (50%) | L20: =L14+L16 -> 308.26212
I21: Valor ideal de venda (100%) | L21: =L14+L17 -> 411.01616
I30: VENDA
L31: =G18+L14 -> 397.00808
I32: Custo por Grama | L32: =L31/F3 -> 397.00808

Sheet cesta Simples
A1: FICHA TÉCNICA
A3: Produto: | B3: cesta Simples | E3: Rendimento: | F3: 1 | H3: Tempo de preparo (min) | J3: 120
A5: Item | D5: Quant. Insumo | E5: Valo do insumo | F5: Quant. Utilizada | G5: Valor custo
A6: cesta | D6: 1 | E6: 30 | F6: 1 | G6: =(F6*E6)/D6 -> 30 | I6: Metodologia Hora Trabalhada
A7: saco | D7: 1 | E7: 3 | F7: 1 | G7: =(F7*E7)/D7 -> 3 | I7: Custo fixo ($/min) | K7: =Custos!F15 -> 0.022037037
A8: balão | D8: 1 | E8: 40 | F8: 1 | G8: =(F8*E8)/D8 -> 40 | I8: Mão de obra ($/min) | K8: =Custos!L15 -> 0.09469697
A9: trufas | D9: 1 | E9: 3.5 | F9: 10 | G9: =(F9*E9)/D9 -> 35
A10: pão de mel | D10: 1 | E10: 8 | F10: 6 | G10: =(F10*E10)/D10 -> 48 | I10: Custo total dos produto
A11: mini bolo | D11: 1 | E11: 18 | F11: 1 | G11: =(F11*E11)/D11 -> 18 | I11: custo fixo | L11: =K7*J3 -> 2.6444444
A12: etiquetas | D12: 1000 | E12: 100 | F12: 3 | G12: =(F12*E12)/D12 -> 0.3 | I12: custo variável | L12: =G18 -> 174.3
I13: mão de obra | L13: =K8*J3 -> 11.363636
I14: Custo total | L14: =SUM(L11:L13) -> 188.30808
I15: Lucro 30% | L15: =L14*0.3 -> 56.492424
I16: Lucro 50% | L16: =L14*0.5 -> 94.15404
I17: Lucro 100% | L17: =L14*1 -> 188.30808
E18: Custo total de matéria-prima | G18: =SUM(G6:G17) -> 174.3
E19: Custo por grama | G19: =(F19*E19)/D19 -> #VALUE! | I19: Valor ideal de venda (30%) | L19: =L14+L15 -> 244.80051
I20: Valor ideal de venda (50%) | L20: =L14+L16 -> 282.46212
I21: Valor ideal de venda (100%) | L21: =L14+L17 -> 376.61616
I30: VENDA
L31: =G18+L14 -> 362.60808
I32: Custo por Grama | L32: =L31/F3 -> 362.60808

Sheet Pasta de Leite em pó
A1: FICHA TÉCNICA
A3: Produto: | B3: Pasta de leite em pó | E3: Rendimento: | F3: 918 | H3: Tempo de preparo (min) | J3: 15
A5: Item | D5: Quant. Insumo | E5: Valo do insumo | F5: Quant. Utilizada | G5: Valor custo
A6: Leite em pó | D6: 900 | E6: 60 | F6: 190 | G6: =(F6*E6)/D6 -> 12.666667 | I6: Metodologia Hora Trabalhada
A7: Açucar impalpavel | D7: 1000 | E7: 17 | F7: 290 | G7: =(F7*E7)/D7 -> 4.93 | I7: Custo fixo (R$/min) | K7: =Custos!F15 -> 0.022037037
A8: merengue em pó | D8: 150 | E8: 14 | F8: 8 | G8: =(F8*E8)/D8 -> 0.74666667 | I8: Mão de obra ($/min) | K8: =Custos!L15 -> 0.09469697
A9: goma xantana | D9: 50 | E9: 18 | F9: 5 | G9: =(F9*E9)/D9 -> 1.8
A10: glucose me milho | D10: 250 | E10: 6 | F10: 30 | G10: =(F10*E10)/D10 -> 0.72 | I10: Custo total dos produto
A11: leite condensado | D11: 395 | E11: 9 | F11: 395 | G11: =(F11*E11)/D11 -> 9 | I11: custo fixo | L11: =K7*J3 -> 0.33055556
D12: 1 | G12: =(F12*E12)/D12 -> 0 | I12: custo variável | L12: =G18 -> 29.863333
D13: 1 | G13: =(F13*E13)/D13 -> 0 | I13: mão de obra | L13: =K8*J3 -> 1.4204545
D14: 1 | G14: =(F14*E14)/D14 -> 0 | I14: Custo total | L14: =SUM(L11:L13) -> 31.614343
D15: 1 | G15: =(F15*E15)/D15 -> 0 | I15: Lucro 30% | L15: =L14*0.3 -> 9.484303
D16: 1 | G16: =(F16*E16)/D16 -> 0 | I16: Valor ideal de venda | L16: =SUM(L14:L15) -> 41.098646
D17: 1 | E17: 0 | F17: 0 | G17: =(F17*E17)/D17 -> 0 | I17: VENDA
E18: Custo total de matéria-prima | G18: =SUM(G6:G17) -> 29.863333
F19: valor por grama | G19: =G18/918 -> 0.032530864

Sheet arroz Doce
A1: FICHA TÉCNICA
A3: Produto: | B3: arroz doce | E3: Rendimento: | F3: 1000 | H3: Tempo de preparo (min) | J3: 30
A5: Item | D5: Quant. Insumo | E5: Valo do insumo | F5: Quant. Utilizada | G5: Valor custo
A6: arroz | D6: 5000 | E6: 30 | F6: 240 | G6: =(F6*E6)/D6 -> 1.44 | I6: Metodologia Hora Trabalhada
A7: açucar | D7: 1000 | E7: 4 | F7: 100 | G7: =(F7*E7)/D7 -> 0.4 | I7: Custo fixo (R$/min) | K7: =Custos!F15 -> 0.022037037
A8: leite | D8: 1000 | E8: 6 | F8: 800 | G8: =(F8*E8)/D8 -> 4.8 | I8: Mão de obra ($/min) | K8: =Custos!L15 -> 0.09469697
A9: cravo | D9: 8 | E9: 5 | F9: 1 | G9: =(F9*E9)/D9 -> 0.625
A10: canela | D10: 10 | E10: 3.3 | F10: 2 | G10: =(F10*E10)/D10 -> 0.66 | I10: Custo total dos produto
I11: custo fixo | L11: =K7*J3 -> 0.66111111
D12: 1 | G12: =(F12*E12)/D12 -> 0 | I12: custo variável | L12: =G18 -> 7.925
D13: 1 | G13: =(F13*E13)/D13 -> 0 | I13: mão de obra | L13: =K8*J3 -> 2.8409091
D14: 1 | G14: =(F14*E14)/D14 -> 0 | I14: Custo total | L14: =SUM(L11:L13) -> 11.42702
D15: 1 | G15: =(F15*E15)/D15 -> 0 | I15: Lucro 30% | L15: =L14*1 -> 11.42702
D16: 1 | G16: =(F16*E16)/D16 -> 0 | I16: Valor ideal de venda | L16: =SUM(L14:L15) -> 22.85404
D17: 1 | E17: 0 | F17: 0 | G17: =(F17*E17)/D17 -> 0 | I17: VENDA
E18: Custo total de matéria-prima | G18: =SUM(G6:G17) -> 7.925
F19: valor por grama | G19: =G18/918 -> 0.0086328976

Sheet Pasta de chocolate
A1: FICHA TÉCNICA
A3: Produto: | B3: Pasta de chocolate | E3: Rendimento: | F3: 125g | H3: Tempo de preparo (min) | J3: 5
A5: Item | D5: Quant. Insumo | E5: Valo do insumo | F5: Quant. Utilizada | G5: Valor custo
A6: chocolate top Branco | D6: 2050 | E6: 55 | F6: 100 | G6: =(F6*E6)/D6 -> 2.6829268 | I6: Metodologia Hora Trabalhada
A7: Glucose | D7: 250 | E7: 6 | F7: 25 | G7: =(F7*E7)/D7 -> 0.6 | I7: Custo fixo (R$/min) | K7: =Custos!F15 -> 0.022037037
G8: =(F8*E8)/D8 -> #DIV/0! | I8: Mão de obra ($/min) | K8: =Custos!L15 -> 0.09469697
G9: =(F9*E9)/D9 -> #DIV/0!
G10: =(F10*E10)/D10 -> #DIV/0! | I10: Custo total dos produto
G11: =(F11*E11)/D11 -> #DIV/0! | I11: custo fixo | L11: =K7*J3 -> 0.11018519
G12: =(F12*E12)/D12 -> #DIV/0! | I12: custo variável | L12: =G18 -> 3.2829268
G13: =(F13*E13)/D13 -> #DIV/0! | I13: mão de obra | L13: =K8*J3 -> 0.47348485
G14: =(F14*E14)/D14 -> #DIV/0! | I14: Custo total | L14: =SUM(L11:L13) -> 3.8665969
G15: =(F15*E15)/D15 -> #DIV/0! | I15: Lucro 30% | L15: =L14*0.3 -> 1.1599791
D16: 1 | G16: =(F16*E16)/D16 -> 0 | I16: Valor ideal de venda | L16: =SUM(L14:L15) -> 5.0265759
D17: 1 | E17: 0 | F17: 0 | G17: =(F17*E17)/D17 -> 0 | I17: VENDA
E18: Custo total de matéria-prima | G18: =SUM(G6:G7) -> 3.2829268
F19: valor por grama | G19: =G18/125 -> 0.026263415

Sheet massa de bolo meia receita
A1: FICHA TÉCNICA
A3: Produto: | B3: Massa de bolo meia receita | E3: Rendimento: | F3: 840 | H3: Tempo de preparo (min) | J3: 30
A5: Item | D5: Quant. Insumo | E5: Valo do insumo | F5: Quant. Utilizada | G5: Valor custo
A6: farinha | D6: 5000 | E6: 20 | F6: 260 | G6: =(F6*E6)/D6 -> 1.04 | I6: Metodologia Hora Trabalhada
A7: ovo | D7: 3000 | E7: 45 | F7: 150 | G7: =(F7*E7)/D7 -> 2.25 | I7: Custo fixo ($/min) | K7: =Custos!F15 -> 0.022037037
A8: fermento | D8: 250 | E8: 9 | F8: 8 | G8: =(F8*E8)/D8 -> 0.288 | I8: Mão de obra ($/min) | K8: =Custos!L15 -> 0.09469697
A9: chocolate em pó | D9: 1000 | E9: 30 | F9: 45 | G9: =(F9*E9)/D9 -> 1.35
A10: açucar | D10: 1000 | E10: 4.5 | F10: 270 | G10: =(F10*E10)/D10 -> 1.215 | I10: Custo total dos produto
A11: agua | D11: 1000 | E11: 2 | F11: 180 | G11: =(F11*E11)/D11 -> 0.36 | I11: custo fixo | L11: =K7*J3 -> 0.66111111
I12: custo variável | L12: =G18 -> 6.503
I13: mão de obra | L13: =K8*J3 -> 2.8409091
I14: Custo total | L14: =SUM(L11:L13) -> 10.00502
I15: Lucro 30% | L15: =L14*0.3 -> 3.0015061
D16: 1 | E16: 0 | F16: 0 | G16: =(F16*E16)/D16 -> 0 | I16: Lucro 50% | L16: =L14*0.5 -> 5.0025101
D17: 1 | E17: 0 | F17: 0 | G17: =(F17*E17)/D17 -> 0 | I17: Lucro 100% | L17: =L14*1 -> 10.00502
E18: Custo total de matéria-prima | G18: =SUM(G6:G17) -> 6.503
E19: Custo por grama | G19: =G18/F3 -> 0.0077416667 | I19: Valor ideal de venda (30%) | L19: =L14+L15 -> 13.006526
I20: Valor ideal de venda (50%) | L20: =L14+L16 -> 15.00753
I21: Valor ideal de venda (100%) | L21: =L14+L17 -> 20.01004
I30: VENDA
L31: =G18+'massa de bolo meia receita'!L1 -> 6.503
I32: Custo por Grama | L32: =L31/F3 -> 0.0077416667

Sheet Biscoitos decorados (2)
A1: FICHA TÉCNICA
A3: Produto: | B3: Biscoitos decorados | E3: Rendimento: | F3: 900 | G3: 110 unidades estrela | H3: Tempo de preparo (min) | J3: 180
A5: Item | D5: Quant. Insumo | E5: Valo do insumo | F5: Quant. Utilizada | G5: Valor custo
A6: farinha | D6: 5000 | E6: 20 | F6: 500 | G6: =(F6*E6)/D6 -> 2 | I6: Metodologia Hora Trabalhada
A7: ovo | D7: 3000 | E7: 45 | F7: 100 | G7: =(F7*E7)/D7 -> 1.5 | I7: Custo fixo ($/min) | K7: =Custos!F15 -> 0.022037037
A8: Manteiga | D8: 200 | E8: 10 | F8: 200 | G8: =(F8*E8)/D8 -> 10 | I8: Mão de obra ($/min) | K8: =Custos!L15 -> 0.09469697
A9: essencia | D9: 30 | E9: 3.19 | F9: 5 | G9: =(F9*E9)/D9 -> 0.53166667
A10: açucar | D10: 1000 | E10: 4.5 | F10: 180 | G10: =(F10*E10)/D10 -> 0.81 | I10: Custo total dos produto
I11: custo fixo | L11: =K7*J3 -> 3.9666667
I12: custo variável | L12: =G18 -> 14.841667
I13: mão de obra | L13: =K8*J3 -> 17.045455
D14: 100 | E14: 32 | F14: 40 | I14: Custo total | L14: =SUM(L11:L13) -> 35.853788
D15: 10 | E15: 12 | F15: 2 | I15: Lucro 30% | L15: =L14*0.3 -> 10.756136
D16: 1 | E16: 0 | F16: 0 | G16: =(F16*E16)/D16 -> 0 | I16: Lucro 50% | L16: =L14*0.5 -> 17.926894
D17: 1 | E17: 0 | F17: 0 | G17: =(F17*E17)/D17 -> 0 | I17: Lucro 100% | L17: =L14*1 -> 35.853788
E18: Custo total de matéria-prima | G18: =SUM(G6:G17) -> 14.841667
E19: Custo por grama | G19: =G18/F3 -> 0.016490741 | I19: Valor ideal de venda (30%) | L19: =L14+L15 -> 46.609924
I20: Valor ideal de venda (50%) | L20: =L14+L16 -> 53.780682
I21: Valor ideal de venda (100%) | L21: =L14+L17 -> 71.707576
I30: VENDA
L31: =G18+'Biscoitos decorados (2)'!L1 -> 14.841667
I32: Custo por Grama | L32: =L31/F3 -> 0.016490741

Sheet Bolo 1kg
A1: FICHA TÉCNICA
A3: Produto: | B3: Bolo 1kg | E3: Rendimento: | F3: 1kg | H3: Tempo de preparo (min) | J3: 200
A5: Item | D5: Quant. Insumo | E5: Valo do insumo | F5: Quant. Utilizada | G5: Valor custo
A6: leite condensado | D6: 395 | E6: 7 | F6: 50 | G6: =(F6*E6)/D6 -> 0.88607595 | I6: Metodologia Hora Trabalhada
A7: creme de leite | D7: 200 | E7: 3.5 | F7: 200 | I7: Custo fixo ($/min) | K7: =Custos!F15 -> 0.022037037
A8: chocolate em pó | D8: 1000 | E8: 32 | F8: 20 | G8: =(F8*E8)/D8 -> 0.64 | I8: Mão de obra ($/min) | K8: =Custos!L15 -> 0.09469697
A9: margarina | D9: 1000 | E9: 15 | F9: 15
A10: abacaxi | D10: 500 | E10: 15 | F10: 300 | G10: =(F10*E10)/D10 -> 9 | I10: Custo total dos produto
A11: massa |Chocolate | D11: 800 | E11: 10 | F11: 400 | G11: =(F11*E11)/D11 -> 5 | I11: custo fixo | L11: =K7*J3 -> 4.4074074
A12: chocolate nobre | D12: 2050 | E12: 130 | F12: 400 | G12: =(F12*E12)/D12 -> 25.365854 | I12: custo variável | L12: =G18 -> 65.64193
A13: creme de leite | D13: 200 | E13: 4 | F13: 300 | G13: =(F13*E13)/D13 -> 6 | I13: mão de obra | L13: =K8*J3 -> 18.939394
I14: Custo total | L14: =SUM(L11:L13) -> 88.988731
A15: chantily | D15: 1000 | E15: 15 | F15: 250 | G15: =(F15*E15)/D15 -> 3.75 | I15: Lucro 30% | L15: =L14*0.3 -> 26.696619
A16: embalagem+cakeboard | D16: 1 | E16: 15 | F16: 1 | G16: =(F16*E16)/D16 -> 15 | I16: Lucro 50% | L16: =L14*0.5 -> 44.494365
I17: Lucro 100% | L17: =L14*1 -> 88.988731
E18: Custo total de matéria-prima | G18: =SUM(G6:G17) -> 65.64193
E19: Custo por grama | G19: =(F19*E19)/D19 -> #VALUE! | I19: Valor ideal de venda (30%) | L19: =L14+L15 -> 115.68535
I20: Valor ideal de venda (50%) | L20: =L14+L16 -> 133.4831
I21: Valor ideal de venda (100%) | L21: =L14+L17 -> 177.97746
I30: VENDA
L31: =G18+L14 -> 154.63066
I32: Custo por Grama | L32: =L31/F3 -> #VALUE!

Sheet Mini BOlo
A1: FICHA TÉCNICA
A3: Produto: | B3: Mini Bolo 500kg | E3: Rendimento: | F3: 500 | H3: Tempo de preparo (min) | J3: 60
A5: Item | D5: Quant. Insumo | E5: Valo do insumo | F5: Quant. Utilizada | G5: Valor custo
A6: massa | D6: 840 | E6: 9 | F6: 190 | G6: =(F6*E6)/D6 -> 2.0357143 | I6: Metodologia Hora Trabalhada
A7: brigadeiro | D7: 500 | E7: 17 | F7: 200 | G7: =(F7*E7)/D7 -> 6.8 | I7: Custo fixo ($/min) | K7: =Custos!F15 -> 0.022037037
A8: abacaxa | D8: 500 | E8: 15 | F8: 70 | G8: =(F8*E8)/D8 -> 2.1 | I8: Mão de obra ($/min) | K8: =Custos!L15 -> 0.09469697
A9: chantily | D9: 200 | E9: 5 | F9: 50 | G9: =(F9*E9)/D9 -> 1.25
A10: prato | D10: 10 | E10: 8 | F10: 1 | G10: =(F10*E10)/D10 -> 0.8 | I10: Custo total dos produto
A11: acetato | D11: 4000 | E11: 7 | F11: 300 | G11: =(F11*E11)/D11 -> 0.525 | I11: custo fixo | L11: =K7*J3 -> 1.3222222
A12: fita | D12: 10000 | E12: 5 | F12: 500 | G12: =(F12*E12)/D12 -> 0.25 | I12: custo variável | L12: =G18 -> 17.760714
A13: embalagem | D13: 5 | E13: 20 | F13: 1 | G13: =(F13*E13)/D13 -> 4 | I13: mão de obra | L13: =K8*J3 -> 5.6818182
I14: Custo total | L14: =SUM(L11:L13) -> 24.764755
I15: Lucro 30% | L15: =L14*0.3 -> 7.4294264
I16: Lucro 50% | L16: =L14*0.5 -> 12.382377
I17: Lucro 100% | L17: =L14*1 -> 24.764755
E18: Custo total de matéria-prima | G18: =SUM(G6:G17) -> 17.760714
E19: Custo por grama | G19: =(F19*E19)/D19 -> #VALUE! | I19: Valor ideal de venda (30%) | L19: =L14+L15 -> 32.194181
I20: Valor ideal de venda (50%) | L20: =L14+L16 -> 37.147132
I21: Valor ideal de venda (100%) | L21: =L14+L17 -> 49.529509
I30: VENDA
L31: =G18+L14 -> 42.525469
I32: Custo por Grama | L32: =L31/F3 -> 0.085050938

Sheet Recheio Bolo de pote
A1: FICHA TÉCNICA
A3: Produto: | B3: Recheio bolo de pote | E3: Rendimento: | F3: 880 | H3: Tempo de preparo (min) | J3: 15
A5: Item | D5: Quant. Insumo | E5: Valo do insumo | F5: Quant. Utilizada | G5: Valor custo
A6: leite condensado | D6: 395 | E6: 7 | F6: 395 | G6: =(F6*E6)/D6 -> 7 | I6: Metodologia Hora Trabalhada
A7: leite | D7: 1000 | E7: 4.5 | F7: 500 | G7: =(F7*E7)/D7 -> 2.25 | I7: Custo fixo ($/min) | K7: =Custos!F15 -> 0.022037037
A8: chocolate em pó | D8: 1000 | E8: 40 | F8: 90 | G8: =(F8*E8)/D8 -> 3.6 | I8: Mão de obra ($/min) | K8: =Custos!L15 -> 0.09469697
A9: farinha | D9: 5000 | E9: 15 | F9: 44 | G9: =(F9*E9)/D9 -> 0.132
A10: ovo | D10: 3000 | E10: 45 | F10: 100 | G10: =(F10*E10)/D10 -> 1.5 | I10: Custo total dos produto
A11: choclate laka | D11: 80 | E11: 9 | F11: 80 | G11: =(F11*E11)/D11 -> 9 | I11: custo fixo | L11: =K7*J3 -> 0.33055556
I12: custo variável | L12: =G18 -> 23.482
I13: mão de obra | L13: =K8*J3 -> 1.4204545
I14: Custo total | L14: =SUM(L11:L13) -> 25.23301
I15: Lucro 30% | L15: =L14*0.3 -> 7.569903
D16: 1 | E16: 0 | F16: 0 | G16: =(F16*E16)/D16 -> 0 | I16: Lucro 50% | L16: =L14*0.5 -> 12.616505
D17: 1 | E17: 0 | F17: 0 | G17: =(F17*E17)/D17 -> 0 | I17: Lucro 100% | L17: =L14*1 -> 25.23301
E18: Custo total de matéria-prima | G18: =SUM(G6:G17) -> 23.482
E19: Custo por grama | G19: =G18/F3 -> 0.026684091 | I19: Valor ideal de venda (30%) | L19: =L14+L15 -> 32.802913
I20: Valor ideal de venda (50%) | L20: =L14+L16 -> 37.849515
I21: Valor ideal de venda (100%) | L21: =L14+L17 -> 50.46602
I30: VENDA
L31: =G18+'Recheio Bolo de pote'!L1 -> 23.482
I32: Custo por Grama | L32: =L31/F3 -> 0.026684091

Sheet Bolo de pote
A1: FICHA TÉCNICA
A3: Produto: | B3: Bolo de pote | E3: Rendimento: | F3: 12 | H3: Tempo de preparo (min) | J3: 5
A5: Item | D5: Quant. Insumo | E5: Valo do insumo | F5: Quant. Utilizada | G5: Valor custo
A6: Massa chocolate | D6: 840 | E6: 9 | F6: 50 | G6: =(F6*E6)/D6 -> 0.53571429 | I6: Metodologia Hora Trabalhada
A7: abacaxi | D7: 500 | E7: 15 | F7: 70 | G7: =(F7*E7)/D7 -> 2.1 | I7: Custo fixo ($/min) | K7: =Custos!F15 -> 0.022037037
A8: chantily | D8: 200 | E8: 5 | F8: 10 | G8: =(F8*E8)/D8 -> 0.25 | I8: Mão de obra ($/min) | K8: =Custos!L15 -> 0.09469697
A9: creme | D9: 880 | E9: 16 | F9: 70 | G9: =(F9*E9)/D9 -> 1.2727273
A10: pote | D10: 20 | E10: 11 | F10: 1 | G10: =(F10*E10)/D10 -> 0.55 | I10: Custo total dos produto
A11: lacre bolo | D11: 100 | E11: 50 | F11: 1 | G11: =(F11*E11)/D11 -> 0.5 | I11: custo fixo | L11: =K7*J3 -> 0.11018519
I12: custo variável | L12: =G18 -> 5.2084416
I13: mão de obra | L13: =K8*J3 -> 0.47348485
I14: Custo total | L14: =SUM(L11:L13) -> 5.7921116
I15: Lucro 30% | L15: =L14*0.3 -> 1.7376335
D16: 1 | E16: 0 | F16: 0 | G16: =(F16*E16)/D16 -> 0 | I16: Lucro 50% | L16: =L14*0.5 -> 2.8960558
D17: 1 | E17: 0 | F17: 0 | G17: =(F17*E17)/D17 -> 0 | I17: Lucro 100% | L17: =L14*1 -> 5.7921116
E18: Custo total de matéria-prima | G18: =SUM(G6:G17) -> 5.2084416
E19: Custo por grama | G19: =G18/F3 -> 0.4340368 | I19: Valor ideal de venda (30%) | L19: =L14+L15 -> 7.5297451
I20: Valor ideal de venda (50%) | L20: =L14+L16 -> 8.6881674
I21: Valor ideal de venda (100%) | L21: =L14+L17 -> 11.584223
I30: VENDA
L31: =G18+L14 -> 11.000553
I32: Custo por Grama | L32: =L31/F3 -> 0.91671276

Sheet B. Cenoura mo pote
A1: FICHA TÉCNICA
A3: Produto: | B3: Bolo de pote cenoura | E3: Rendimento: | F3: 1 | H3: Tempo de preparo (min) | J3: 8
A5: Item | D5: Quant. Insumo | E5: Valo do insumo | F5: Quant. Utilizada | G5: Valor custo
A6: Massa chocolate | D6: 1000 | E6: 19 | F6: 80 | G6: =(F6*E6)/D6 -> 1.52 | I6: Metodologia Hora Trabalhada
A7: Recheio Brigadeiro | D7: 500 | E7: 18 | F7: 100 | G7: =(F7*E7)/D7 -> 3.6 | I7: Custo fixo ($/min) | K7: =Custos!F15 -> 0.022037037
A8: Granulado | D8: 400 | E8: 35 | F8: 10 | G8: =(F8*E8)/D8 -> 0.875 | I8: Mão de obra ($/min) | K8: =Custos!L15 -> 0.09469697
A9: pote | D9: 20 | E9: 15 | F9: 1 | G9: =(F9*E9)/D9 -> 0.75
I10: Custo total dos produto
I11: custo fixo | L11: =K7*J3 -> 0.1762963
I12: custo variável | L12: =G18 -> 6.745
I13: mão de obra | L13: =K8*J3 -> 0.75757576
I14: Custo total | L14: =SUM(L11:L13) -> 7.6788721
I15: Lucro 30% | L15: =L14*0.3 -> 2.3036616
D16: 1 | E16: 0 | F16: 0 | G16: =(F16*E16)/D16 -> 0 | I16: Lucro 50% | L16: =L14*0.5 -> 3.839436
D17: 1 | E17: 0 | F17: 0 | G17: =(F17*E17)/D17 -> 0 | I17: Lucro 100% | L17: =L14*1 -> 7.6788721
E18: Custo total de matéria-prima | G18: =SUM(G6:G17) -> 6.745
E19: Custo por grama | G19: =G18/F3 -> 6.745 | I19: Valor ideal de venda (30%) | L19: =L14+L15 -> 9.9825337
I20: Valor ideal de venda (50%) | L20: =L14+L16 -> 11.518308
I21: Valor ideal de venda (100%) | L21: =L14+L17 -> 15.357744
I30: VENDA
L31: =G18+L14 -> 14.423872
I32: Custo por Grama | L32: =L31/F3 -> 14.423872

Sheet Sonho
A1: FICHA TÉCNICA
A3: Produto: | B3: sonho | E3: Rendimento: | F3: 30 | H3: Tempo de preparo (min) | J3: 180
A5: Item | D5: Quant. Insumo | E5: Valo do insumo | F5: Quant. Utilizada | G5: Valor custo
A6: Farinha | D6: 1000 | E6: 5 | F6: 500 | G6: =(F6*E6)/D6 -> 2.5 | I6: Metodologia Hora Trabalhada
A7: Leite | D7: 1000 | E7: 6 | F7: 250 | G7: =(F7*E7)/D7 -> 1.5 | I7: Custo fixo (R$/min) | K7: =Custos!F15 -> 0.022037037
A8: Gemas | D8: 30 | E8: 20 | F8: 6 | G8: =(F8*E8)/D8 -> 4 | I8: Mão de obra ($/min) | K8: =Custos!L15 -> 0.09469697
A9: sal | D9: 1000 | E9: 3 | F9: 4 | G9: =(F9*E9)/D9 -> 0.012
A10: Açucar | D10: 1000 | E10: 4.5 | F10: 75 | G10: =(F10*E10)/D10 -> 0.3375 | I10: Custo total dos produto
A11: Margarina | D11: 1000 | E11: 14 | F11: 50 | G11: =(F11*E11)/D11 -> 0.7 | I11: custo fixo | L11: =K7*J3 -> 3.9666667
A12: Fermento Biologico | D12: 125 | E12: 9 | F12: 12 | G12: =(F12*E12)/D12 -> 0.864 | I12: custo variável | L12: =G18 -> 49.9805
A13: Melhorador | D13: 10 | E13: 2.5 | F13: 5 | G13: =(F13*E13)/D13 -> 1.25 | I13: mão de obra | L13: =K8*J3 -> 17.045455
A14: Essencia de Baunilha | D14: 10 | E14: 3.17 | F14: 1 | G14: =(F14*E14)/D14 -> 0.317 | I14: Custo total | L14: =SUM(L11:L13) -> 70.992621
A15: Recheio Laka | D15: 1200 | E15: 27 | F15: 1200 | G15: =(F15*E15)/D15 -> 27 | I15: Lucro 100% | L15: =L14*1 -> 70.992621
A16: cobertura | D16: 380 | E16: 19 | F16: 50 | G16: =(F16*E16)/D16 -> 2.5 | I16: Valor ideal de venda | L16: =SUM(L14:L15) -> 141.98524
A17: óleo | D17: 900 | E17: 9 | F17: 900 | G17: =(F17*E17)/D17 -> 9 | I17: VENDA
E18: Custo total de matéria-prima | G18: =SUM(G6:G17) -> 49.9805

Sheet Pipoca caramelada
A1: FICHA TÉCNICA
A3: Produto: | B3: Pipoca Caramelada | E3: Rendimento: | F3: 240g 4 unidades de 60g | H3: Tempo de preparo (min) | J3: 30
A5: Item | D5: Quant. Insumo | E5: Valo do insumo | F5: Quant. Utilizada | G5: Valor custo
A6: milho | D6: 500 | E6: 13 | F6: 75 | G6: =F6*E6/D6 -> 1.95 | I6: Metodologia Hora Trabalhada
A7: manteiga | D7: 200 | E7: 12 | F7: 40 | G7: =F7*E7/D7 -> 2.4 | I7: Custo fixo (R$/min) | K7: =Custos!F15 -> 0.022037037
A8: açucar | D8: 1000 | E8: 4.5 | F8: 160 | G8: =F8*E8/D8 -> 0.72 | I8: Mão de obra ($/min) | K8: =Custos!L15 -> 0.09469697
A9: etiquetas | D9: 1000 | E9: 100 | F9: 4 | G9: =F9*E9/D9 -> 0.4
A10: saquinho | D10: 100 | E10: 7 | F10: 4 | G10: =F10*E10/D10 -> 0.28 | I10: Custo total dos produto
I11: custo fixo | L11: =K7*J3 -> 0.66111111
I12: custo variável | L12: =G18 -> 5.75
I13: mão de obra | L13: =K8*J3 -> 2.8409091
I14: Custo total | L14: =SUM(L11:L13) -> 9.2520202
I15: Lucro 30% | L15: =L14*1 -> 9.2520202
D16: 1 | I16: Valor ideal de venda | L16: =SUM(L14+L15) -> 18.50404
D17: 1 | E17: 0 | F17: 0 | I17: VENDA
E18: Custo total de matéria-prima | G18: =SUM(G6:H17) -> 5.75

Sheet Pipoca Ninho
A1: FICHA TÉCNICA
A3: Produto: | B3: Pipoca Ninho | E3: Rendimento: | F3: 4 unidades de 100g | H3: Tempo de preparo (min) | J3: 60
A5: Item | D5: Quant. Insumo | E5: Valo do insumo | F5: Quant. Utilizada | G5: Valor custo
A6: milho | D6: 500 | E6: 13 | F6: 75 | G6: =F6*E6/D6 -> 1.95 | I6: Metodologia Hora Trabalhada
A7: manteiga | D7: 200 | E7: 12 | F7: 40 | G7: =F7*E7/D7 -> 2.4 | I7: Custo fixo (R$/min) | K7: =Custos!F15 -> 0.022037037
A8: açucar | D8: 1000 | E8: 4.5 | F8: 160 | G8: =F8*E8/D8 -> 0.72 | I8: Mão de obra ($/min) | K8: =Custos!L15 -> 0.09469697
A9: etiquetas | D9: 1000 | E9: 100 | F9: 4 | G9: =F9*E9/D9 -> 0.4
A10: saquinho | D10: 100 | E10: 7 | F10: 4 | G10: =F10*E10/D10 -> 0.28 | I10: Custo total dos produto
A11: Chocolate branco | D11: 2050 | E11: 65 | F11: 240 | G11: =F11*E11/D11 -> 7.6097561 | I11: custo fixo | L11: =K7*J3 -> 1.3222222
A12: ninho | D12: 900 | E12: 55 | F12: 80 | G12: =F12*E12/D12 -> 4.8888889 | I12: custo variável | L12: =G18 -> 18.248645
I13: mão de obra | L13: =K8*J3 -> 5.6818182
I14: Custo total | L14: =SUM(L11:L13) -> 25.252685
I15: Lucro 30% | L15: =L14*1 -> 25.252685
D16: 1 | I16: Valor ideal de venda | L16: =SUM(L14+L15) -> 50.505371
D17: 1 | E17: 0 | F17: 0 | I17: VENDA
E18: Custo total de matéria-prima | G18: =SUM(G6:H17) -> 18.248645

Sheet Biscoitos decorados
A1: FICHA TÉCNICA
A3: Produto: | B3: Biscoitos decorados | E3: Rendimento: | F3: 900 | G3: 40 unidades | H3: Tempo de preparo (min) | J3: 240
A5: Item | D5: Quant. Insumo | E5: Valo do insumo | F5: Quant. Utilizada | G5: Valor custo
A6: farinha | D6: 5000 | E6: 20 | F6: 500 | G6: =(F6*E6)/D6 -> 2 | I6: Metodologia Hora Trabalhada
A7: ovo | D7: 3000 | E7: 45 | F7: 100 | G7: =(F7*E7)/D7 -> 1.5 | I7: Custo fixo ($/min) | K7: =Custos!F15 -> 0.022037037
A8: Manteiga | D8: 200 | E8: 10 | F8: 200 | G8: =(F8*E8)/D8 -> 10 | I8: Mão de obra ($/min) | K8: =Custos!L15 -> 0.09469697
A9: essencia | D9: 30 | E9: 3.19 | F9: 5 | G9: =(F9*E9)/D9 -> 0.53166667
A10: açucar | D10: 1000 | E10: 4.5 | F10: 180 | G10: =(F10*E10)/D10 -> 0.81 | I10: Custo total dos produto
A11: chocolate top | D11: 2050 | E11: 80 | F11: 150 | I11: custo fixo | L11: =K7*J3 -> 5.2888889
A12: saquinho 11x19 | D12: 100 | E12: 6 | F12: 20 | G12: =(F12*E12)/D12 -> 1.2 | I12: custo variável | L12: =G18 -> 41.841667
A13: fita cetinho | D13: 10000 | E13: 14 | F13: 10000 | G13: =(F13*E13)/D13 -> 14 | I13: mão de obra | L13: =K8*J3 -> 22.727273
A14: tag | D14: 100 | E14: 43 | F14: 20 | G14: =(F14*E14)/D14 -> 8.6 | I14: Custo total | L14: =SUM(L11:L13) -> 69.857828
A15: sacola | D15: 10 | E15: 12 | F15: 2 | G15: =(F15*E15)/D15 -> 2.4 | I15: Lucro 30% | L15: =L14*0.3 -> 20.957348
A16: arame | D16: 100 | E16: 4 | F16: 20 | G16: =(F16*E16)/D16 -> 0.8 | I16: Lucro 50% | L16: =L14*0.5 -> 34.928914
D17: 1 | E17: 0 | F17: 0 | G17: =(F17*E17)/D17 -> 0 | I17: Lucro 100% | L17: =L14*1 -> 69.857828
E18: Custo total de matéria-prima | G18: =SUM(G6:G17) -> 41.841667
E19: Custo por grama | G19: =G18/F3 -> 0.046490741 | I19: Valor ideal de venda (30%) | L19: =L14+L15 -> 90.815177
I20: Valor ideal de venda (50%) | L20: =L14+L16 -> 104.78674
I21: Valor ideal de venda (100%) | L21: =L14+L17 -> 139.71566
I30: VENDA
L31: =G18+'Biscoitos decorados'!L1 -> 41.841667
I32: Custo por Grama | L32: =L31/F3 -> 0.046490741

Sheet cone trufado 80g
A1: FICHA TÉCNICA
A3: Produto: | B3: cone trufado 80g | E3: Rendimento: | F3: 1 | H3: Tempo de preparo (min) | J3: 10
A5: Item | D5: Quant. Insumo | E5: Valo do insumo | F5: Quant. Utilizada | G5: Valor custo
A6: cone de sorvete | D6: 300 | E6: 75 | F6: 1 | G6: =(F6*E6)/D6 -> 0.25 | I6: Metodologia Hora Trabalhada
A7: chocolate cobertura | D7: 2050 | E7: 65 | F7: 15 | G7: =(F7*E7)/D7 -> 0.47560976 | I7: Custo fixo (R$/min) | K7: =Custos!F15 -> 0.022037037
A8: brigadeiro | D8: 500 | E8: 22 | F8: 50 | G8: =(F8*E8)/D8 -> 2.2 | I8: Mão de obra (R$/min) | K8: =Custos!L15 -> 0.09469697
A9: granule | D9: 400 | E9: 50 | F9: 4 | G9: =(F9*E9)/D9 -> 0.5
A10: saquinho cone | D10: 50 | E10: 15 | F10: 1 | G10: =(F10*E10)/D10 -> 0.3 | I10: Custo total dos produto
A11: etiqueta perso | D11: 1000 | E11: 100 | F11: 1 | G11: =(F11*E11)/D11 -> 0.1 | I11: custo fixo | L11: =K7*J3 -> 0.22037037
A12: pasta de leite | D12: 900 | E12: 29 | F12: 100 | I12: custo variável | L12: =G18 -> 4.3206098
A13: tag | D13: 200 | E13: 43 | F13: 1 | G13: =(F13*E13)/D13 -> 0.215 | I13: mão de obra | L13: =K8*J3 -> 0.9469697
A14: fita | D14: 10000 | E14: 14 | F14: 200 | G14: =(F14*E14)/D14 -> 0.28 | I14: Custo total | L14: =SUM(L11:L13) -> 5.4879498
D15: 1 | F15: 1 | G15: =(F15*E15)/D15 -> 0 | I15: Lucro 30% | L15: =L14*0.3 -> 1.6463849
D16: 1 | E16: 0 | F16: 0 | G16: =(F16*E16)/D16 -> 0 | I16: Lucro 50% | L16: =L14*0.5 -> 2.7439749
D17: 1 | E17: 0 | F17: 0 | G17: =(F17*E17)/D17 -> 0 | I17: Lucro 100% | L17: =L14*1 -> 5.4879498
E18: Custo total de matéria-prima | G18: =SUM(G6:G14) -> 4.3206098
E19: Custo por grama | I19: Valor ideal de venda (30%) | L19: =L14+L15 -> 7.1343348
I20: Valor ideal de venda (50%) | L20: =L14+L16 -> 8.2319247
I21: Valor ideal de venda (100%) | L21: =L14+L17 -> 10.9759

Sheet bolo no palito
A1: FICHA TÉCNICA
A3: Produto: | B3: Bolo no Palito | E3: Rendimento: | F3: 1 | H3: Tempo de preparo (min) | J3: 30
A5: Item | D5: Quant. Insumo | E5: Valo do insumo | F5: Quant. Utilizada | G5: Valor custo
A6: chocolate top Branco | D6: 2050 | E6: 65 | F6: 50 | G6: =(F6*E6)/D6 -> 1.5853659 | I6: Metodologia Hora Trabalhada
A7: brigadeiro | D7: 500 | E7: 17 | F7: 50 | G7: =(F7*E7)/D7 -> 1.7 | I7: Custo fixo (R$/min) | K7: =Custos!F15 -> 0.022037037
A8: Massa pão de mel | D8: 1500 | E8: 21 | F8: 30 | G8: =(F8*E8)/D8 -> 0.42 | I8: Mão de obra ($/min) | K8: =Custos!L15 -> 0.09469697
D9: 1 | G9: =(F9*E9)/D9 -> 0
A10: saquinho | D10: 100 | E10: 5 | F10: 1 | G10: =(F10*E10)/D10 -> 0.05 | I10: Custo total dos produto
A11: fita | D11: 1000 | E11: 5 | F11: 150 | G11: =(F11*E11)/D11 -> 0.75 | I11: custo fixo | L11: =K7*J3 -> 0.66111111
A12: palito | D12: 100 | E12: 5 | F12: 1 | G12: =(F12*E12)/D12 -> 0.05 | I12: custo variável | L12: =G18 -> 5.6086992
A13: Pasta leite | D13: 900 | E13: 31.6 | F13: 30 | G13: =(F13*E13)/D13 -> 1.0533333 | I13: mão de obra | L13: =K8*J3 -> 2.8409091
D14: 1 | G14: =(F14*E14)/D14 -> 0 | I14: Custo total | L14: =SUM(L11:L13) -> 9.1107194
D15: 1 | G15: =(F15*E15)/D15 -> 0 | I15: Lucro 30% | L15: =L14*1 -> 9.1107194
D16: 1 | E16: 0 | F16: 0 | G16: =(F16*E16)/D16 -> 0 | I16: Valor ideal de venda | L16: =SUM(L14:L15) -> 18.221439
D17: 1 | E17: 0 | F17: 0 | G17: =(F17*E17)/D17 -> 0 | I17: VENDA
E18: Custo total de matéria-prima | G18: =SUM(G6:G13) -> 5.6086992

Sheet Trufa M
A1: FICHA TÉCNICA
A3: Produto: | B3: Trufa M | E3: Rendimento: | F3: 1 | H3: Tempo de preparo (min) | J3: 15
A5: Item | D5: Quant. Insumo | E5: Valo do insumo | F5: Quant. Utilizada | G5: Valor custo
A6: chocolate top Branco | D6: 2050 | E6: 65 | F6: 16 | G6: =(F6*E6)/D6 -> 0.50731707 | I6: Metodologia Hora Trabalhada
A7: brigadeiro Recheio | D7: 500 | E7: 16 | F7: 30 | G7: =(F7*E7)/D7 -> 0.96 | I7: Custo fixo (R$/min) | K7: =Custos!F15 -> 0.022037037
A8: trufa pistache | D8: 244 | E8: 15.77 | F8: 30 | I8: Mão de obra ($/min) | K8: =Custos!L15 -> 0.09469697
A9: corante | D9: 12 | E9: 5 | F9: 1 | G9: =(F9*E9)/D9 -> 0.41666667
A10: pasta de leite | D10: 800 | E10: 31.6 | F10: 50 | G10: =(F10*E10)/D10 -> 1.975 | I10: Custo total dos produto
G11: =(F11*E11)/D11 -> #DIV/0! | I11: custo fixo | L11: =K7*J3 -> 0.33055556
G12: =(F12*E12)/D12 -> #DIV/0! | I12: custo variável | L12: =G18 -> 3.8589837
G13: =(F13*E13)/D13 -> #DIV/0! | I13: mão de obra | L13: =K8*J3 -> 1.4204545
G14: =(F14*E14)/D14 -> #DIV/0! | I14: Custo total | L14: =SUM(L11:L13) -> 5.6099938
G15: =(F15*E15)/D15 -> #DIV/0! | I15: Lucro 30% | L15: =L14*1 -> 5.6099938
D16: 1 | G16: =(F16*E16)/D16 -> 0 | I16: Valor ideal de venda | L16: =SUM(L14+L15) -> 11.219988
D17: 1 | E17: 0 | F17: 0 | G17: =(F17*E17)/D17 -> 0 | I17: VENDA
E18: Custo total de matéria-prima | G18: =SUM(G6:G10) -> 3.8589837

Sheet Biscoitos estrelinha Natal
A1: FICHA TÉCNICA
A3: Produto: | B3: Biscoitos estrelinhas natal | E3: Rendimento: | F3: 900 | G3: 110 unidades estrela | H3: Tempo de preparo (min) | J3: 180
A5: Item | D5: Quant. Insumo | E5: Valo do insumo | F5: Quant. Utilizada | G5: Valor custo
A6: farinha | D6: 5000 | E6: 20 | F6: 500 | G6: =(F6*E6)/D6 -> 2 | I6: Metodologia Hora Trabalhada
A7: ovo | D7: 3000 | E7: 45 | F7: 100 | G7: =(F7*E7)/D7 -> 1.5 | I7: Custo fixo ($/min) | K7: =Custos!F15 -> 0.022037037
A8: Manteiga | D8: 200 | E8: 10 | F8: 200 | G8: =(F8*E8)/D8 -> 10 | I8: Mão de obra ($/min) | K8: =Custos!L15 -> 0.09469697
A9: essencia | D9: 30 | E9: 3.19 | F9: 5 | G9: =(F9*E9)/D9 -> 0.53166667
A10: açucar | D10: 1000 | E10: 4.5 | F10: 180 | G10: =(F10*E10)/D10 -> 0.81 | I10: Custo total dos produto
A11: saquinho | D11: 50 | E11: 6 | F11: 20 | G11: =(F11*E11)/D11 -> 2.4 | I11: custo fixo | L11: =K7*J3 -> 3.9666667
A12: sacola | D12: 10 | E12: 12 | F12: 1 | G12: =(F12*E12)/D12 -> 1.2 | I12: custo variável | L12: =G18 -> 30.861667
A13: tag | D13: 200 | E13: 43 | F13: 20 | G13: =(F13*E13)/D13 -> 4.3 | I13: mão de obra | L13: =K8*J3 -> 17.045455
A14: etiqueta | D14: 1000 | E14: 100 | F14: 20 | G14: =(F14*E14)/D14 -> 2 | I14: Custo total | L14: =SUM(L11:L13) -> 51.873788
A15: fita | D15: 10000 | E15: 14 | F15: 3800 | G15: =(F15*E15)/D15 -> 5.32 | I15: Lucro 30% | L15: =L14*0.3 -> 15.562136
A16: arame | D16: 100 | E16: 4 | F16: 20 | G16: =(F16*E16)/D16 -> 0.8 | I16: Lucro 50% | L16: =L14*0.5 -> 25.936894
D17: 1 | E17: 0 | F17: 0 | G17: =(F17*E17)/D17 -> 0 | I17: Lucro 100% | L17: =L14*1 -> 51.873788
E18: Custo total de matéria-prima | G18: =SUM(G6:G17) -> 30.861667
E19: Custo por grama | G19: =G18/F3 -> 0.034290741 | I19: Valor ideal de venda (30%) | L19: =L14+L15 -> 67.435924
I20: Valor ideal de venda (50%) | L20: =L14+L16 -> 77.810682
I21: Valor ideal de venda (100%) | L21: =L14+L17 -> 103.74758
B22: 20 saqinhos
I30: VENDA
L31: =G18+'Biscoitos estrelinha Natal'!L1 -> 30.861667
I32: Custo por Grama | L32: =L31/F3 -> 0.034290741

Sheet Mini cake donuts
A1: FICHA TÉCNICA
A3: Produto: | B3: Mini cake donuts | E3: Rendimento: | F3: 425g meia receita | G3: 20 | H3: Tempo de preparo (min) | J3: 100
A5: Item | D5: Quant. Insumo | E5: Valo do insumo | F5: Quant. Utilizada | G5: Valor custo
A6: farinha | D6: 5000 | E6: 20 | F6: 125 | G6: =(F6*E6)/D6 -> 0.5 | I6: Metodologia Hora Trabalhada
A7: ovo | D7: 3000 | E7: 45 | F7: 50 | G7: =(F7*E7)/D7 -> 0.75 | I7: Custo fixo ($/min) | K7: =Custos!F15 -> 0.022037037
A8: Manteiga | D8: 200 | E8: 10 | F8: 30 | G8: =(F8*E8)/D8 -> 1.5 | I8: Mão de obra ($/min) | K8: =Custos!L15 -> 0.09469697
A9: essencia | D9: 30 | E9: 3.19 | F9: 5 | G9: =(F9*E9)/D9 -> 0.53166667
A10: açucar | D10: 1000 | E10: 4.5 | F10: 70 | G10: =(F10*E10)/D10 -> 0.315 | I10: Custo total dos produto
A11: oleo | D11: 900 | E11: 9 | F11: 10 | G11: =(F11*E11)/D11 -> 0.1 | I11: custo fixo | L11: =K7*J3 -> 2.2037037
A12: sacola | D12: 10 | E12: 12 | F12: 1 | G12: =(F12*E12)/D12 -> 1.2 | I12: custo variável | L12: =G22 -> 26.204715
A13: tag | D13: 200 | E13: 43 | F13: 25 | G13: =(F13*E13)/D13 -> 5.375 | I13: mão de obra | L13: =K8*J3 -> 9.469697
A14: etiqueta | D14: 1000 | E14: 100 | F14: 25 | G14: =(F14*E14)/D14 -> 2.5 | I14: Custo total | L14: =SUM(L11:L13) -> 37.878116
A15: fita | D15: 10000 | E15: 14 | F15: 4750 | G15: =(F15*E15)/D15 -> 6.65 | I15: Lucro 30% | L15: =L14*0.3 -> 11.363435
A16: arame | D16: 100 | E16: 4 | F16: 25 | G16: =(F16*E16)/D16 -> 1 | I16: Lucro 50% | L16: =L14*0.5 -> 18.939058
A17: leite | D17: 1000 | E17: 5 | F17: 125 | G17: =(F17*E17)/D17 -> 0.625 | I17: Lucro 100% | L17: =L14*1 -> 37.878116
B18: chocolate | D18: 2050 | E18: 80 | F18: 125 | G18: =(F18*E18)/D18 -> 4.8780488
B19: fermento | D19: 250 | E19: 10 | F19: 7 | G19: =(F19*E19)/D19 -> 0.28 | I19: Valor ideal de venda (30%) | L19: =L14+L15 -> 49.241551
I20: Valor ideal de venda (50%) | L20: =L14+L16 -> 56.817174
I21: Valor ideal de venda (100%) | L21: =L14+L17 -> 75.756232
E22: Custo total de matéria-prima | G22: =SUM(G6:G19) -> 26.204715
E23: Custo por grama | G23: =G22/F3 -> #VALUE!
I30: VENDA
L31: =G22+'Mini cake donuts'!L1 -> 26.204715
I32: Custo por Grama | L32: =L31/F3 -> #VALUE!

Sheet Biscoitos de gengibre
A1: FICHA TÉCNICA
A3: Produto: | B3: Biscoito de gengibre | E3: Rendimento: | G3: 20 bonecos | H3: Tempo de preparo (min) | J3: 300
A5: Item | D5: Quant. Insumo | E5: Valo do insumo | F5: Quant. Utilizada | G5: Valor custo
A6: farinha | D6: 5000 | E6: 20 | F6: 500 | G6: =(F6*E6)/D6 -> 2 | I6: Metodologia Hora Trabalhada
A7: ovo | D7: 3000 | E7: 45 | F7: 50 | G7: =(F7*E7)/D7 -> 0.75 | I7: Custo fixo ($/min) | K7: =Custos!F15 -> 0.022037037
A8: Manteiga | D8: 200 | E8: 10 | F8: 100 | G8: =(F8*E8)/D8 -> 5 | I8: Mão de obra ($/min) | K8: =Custos!L15 -> 0.09469697
A9: gengibre | D9: 100 | E9: 5 | F9: 2 | G9: =(F9*E9)/D9 -> 0.1
A10: açucar mascavo | D10: 1000 | E10: 12 | F10: 80 | G10: =(F10*E10)/D10 -> 0.96 | I10: Custo total dos produto
A11: glace real | D11: 500 | E11: 10 | F11: 200 | G11: =(F11*E11)/D11 -> 4 | I11: custo fixo | L11: =K7*J3 -> 6.6111111
A12: saquinho 11x19 | D12: 100 | E12: 10 | F12: 20 | G12: =(F12*E12)/D12 -> 2 | I12: custo variável | L12: =G23 -> 42.13
A13: fita cetinho | D13: 10000 | E13: 14 | F13: 10000 | G13: =(F13*E13)/D13 -> 14 | I13: mão de obra | L13: =K8*J3 -> 28.409091
A14: melado | D14: 250 | E14: 8 | F14: 160 | G14: =(F14*E14)/D14 -> 5.12 | I14: Custo total | L14: =SUM(L11:L13) -> 77.150202
A15: cravo | D15: 100 | E15: 5 | F15: 1 | G15: =(F15*E15)/D15 -> 0.05 | I15: Lucro 30% | L15: =L14*0.3 -> 23.145061
A16: bicarbonato | D16: 200 | E16: 10 | F16: 5 | G16: =(F16*E16)/D16 -> 0.25 | I16: Lucro 50% | L16: =L14*0.5 -> 38.575101
A17: canela | D17: 100 | E17: 50 | F17: 3 | G17: =(F17*E17)/D17 -> 1.5 | I17: Lucro 100% | L17: =L14*1 -> 77.150202
B18: TAG | D18: 200 | E18: 43 | F18: 20 | G18: 4.2
B19: arame | D19: 100 | E19: 4 | F19: 20 | G19: 0.8 | I19: Valor ideal de venda (30%) | L19: =L14+L15 -> 100.29526
B20: sacola | D20: 10 | E20: 14 | F20: 1 | G20: 1.4 | I20: Valor ideal de venda (50%) | L20: =L14+L16 -> 115.7253
I21: Valor ideal de venda (100%) | L21: =L14+L17 -> 154.3004
E23: Custo total de matéria-prima | G23: =SUM(G6:G21) -> 42.13
E24: Custo por grama | G24: =G23/F3 -> #DIV/0!
I30: VENDA
L31: =G23+'Biscoitos de gengibre'!L1 -> 42.13
I32: Custo por Grama | L32: =L31/F3 -> #DIV/0!

Sheet BBBrowmie
A1: FICHA TÉCNICA
A3: Produto: | B3: Bbbrowmie | E3: Rendimento: | G3: 1 | H3: Tempo de preparo (min) | J3: 5
A5: Item | D5: Quant. Insumo | E5: Valo do insumo | F5: Quant. Utilizada | G5: Valor custo
A6: chocolate top Branco | D6: 2050 | E6: 80 | F6: 22 | G6: =(F6*E6)/D6 -> 0.85853659 | I6: Metodologia Hora Trabalhada
A7: brigadeiro Recheio | D7: 500 | E7: 18 | F7: 20 | G7: =(F7*E7)/D7 -> 0.72 | I7: Custo fixo (R$/min) | K7: =Custos!F15 -> 0.022037037
A8: brownie | D8: 2000 | E8: 92 | F8: 25 | G8: =(F8*E8)/D8 -> 1.15 | I8: Mão de obra ($/min) | K8: =Custos!L15 -> 0.09469697
A9: tag | D9: 200 | E9: 43 | F9: 1 | G9: =(F9*E9)/D9 -> 0.215
A10: etiqueta | D10: 1000 | E10: 100 | F10: 1 | G10: =(F10*E10)/D10 -> 0.1 | I10: Custo total dos produto
A11: arame | D11: 100 | E11: 4 | F11: 1 | G11: =(F11*E11)/D11 -> 0.04 | I11: custo fixo | L11: =K7*J3 -> 0.11018519
A12: sacola | D12: 10 | E12: 12 | F12: 1 | I12: custo variável | L12: =G18 -> 3.3495366
A13: fita cetim | D13: 10000 | E13: 14 | F13: 190 | G13: =(F13*E13)/D13 -> 0.266 | I13: mão de obra | L13: =K8*J3 -> 0.47348485
I14: Custo total | L14: =SUM(L11:L13) -> 3.9332066
I15: Lucro 30% | L15: =L14*1 -> 3.9332066
D16: 1 | G16: =(F16*E16)/D16 -> 0 | I16: Valor ideal de venda | L16: =SUM(L14+L15) -> 7.8664132
D17: 1 | E17: 0 | F17: 0 | G17: =(F17*E17)/D17 -> 0 | I17: VENDA
E18: Custo total de matéria-prima | G18: =SUM(G6:G13) -> 3.3495366

Sheet pão de mel Boneco
A1: FICHA TÉCNICA
A3: Produto: | B3: Pão de mel Boneco | E3: Rendimento: | F3: 1 | H3: Tempo de preparo (min) | J3: 15
A5: Item | D5: Quant. Insumo | E5: Valo do insumo | F5: Quant. Utilizada | G5: Valor custo
A6: chocolate top Branco | D6: 2050 | E6: 80 | F6: 30 | G6: =(F6*E6)/D6 -> 1.1707317 | I6: Metodologia Hora Trabalhada
A7: brigadeiro | D7: 900 | E7: 18 | F7: 22 | G7: =(F7*E7)/D7 -> 0.44 | I7: Custo fixo (R$/min) | K7: =Custos!F15 -> 0.022037037
A8: Massa pão de mel | D8: 1500 | E8: 21 | F8: 20 | G8: =(F8*E8)/D8 -> 0.28 | I8: Mão de obra ($/min) | K8: =Custos!L15 -> 0.09469697
A9: saquinho | D9: 100 | E9: 5 | F9: 1 | G9: =(F9*E9)/D9 -> 0.05
A10: etiqueta | D10: 1000 | E10: 100 | F10: 1 | G10: =(F10*E10)/D10 -> 0.1 | I10: Custo total dos produto
A11: caixa | D11: 10 | E11: 9 | F11: 1 | G11: =(F11*E11)/D11 -> 0.9 | I11: custo fixo | L11: =K7*J3 -> 0.33055556
A12: fita | D12: 10000 | E12: 14 | G12: =(F12*E12)/D12 -> 0 | I12: custo variável | L12: =G18 -> 2.0407317
A13: tag | D13: 200 | E13: 43 | F13: 1 | G13: =(F13*E13)/D13 -> 0.215 | I13: mão de obra | L13: =K8*J3 -> 1.4204545
A14: pasta leite | D14: 900 | E14: 30 | F14: 10 | G14: =(F14*E14)/D14 -> 0.33333333 | I14: Custo total | L14: =SUM(L11:L13) -> 3.7917418
D15: 1 | G15: =(F15*E15)/D15 -> 0 | I15: Lucro 100% | L15: =L14*1 -> 3.7917418
D16: 1 | E16: 0 | F16: 0 | G16: =(F16*E16)/D16 -> 0 | I16: Valor ideal de venda | L16: =SUM(L14:L15) -> 7.5834836
D17: 1 | E17: 0 | F17: 0 | G17: =(F17*E17)/D17 -> 0 | I17: VENDA
E18: Custo total de matéria-prima | G18: =SUM(G6:G10) -> 2.0407317

Sheet 3 Browmie
A1: FICHA TÉCNICA
A3: Produto: | B3: 3 browmie | E3: Rendimento: | G3: 1 | H3: Tempo de preparo (min) | J3: 10
A5: Item | D5: Quant. Insumo | E5: Valo do insumo | F5: Quant. Utilizada | G5: Valor custo
A6: chocolate top Branco | D6: 2050 | E6: 80 | F6: 6 | G6: =(F6*E6)/D6 -> 0.23414634 | I6: Metodologia Hora Trabalhada
A7: brigadeiro Recheio | D7: 500 | E7: 18 | F7: 3 | G7: =(F7*E7)/D7 -> 0.108 | I7: Custo fixo (R$/min) | K7: =Custos!F15 -> 0.022037037
A8: brownie | D8: 2000 | E8: 92 | F8: 80 | G8: =(F8*E8)/D8 -> 3.68 | I8: Mão de obra ($/min) | K8: =Custos!L15 -> 0.09469697
A9: tag | D9: 200 | E9: 43 | F9: 1 | G9: =(F9*E9)/D9 -> 0.215
A10: etiqueta | D10: 1000 | E10: 100 | F10: 1 | G10: =(F10*E10)/D10 -> 0.1 | I10: Custo total dos produto
A11: tapetinho | D11: 100 | E11: 2 | F11: 3 | G11: =(F11*E11)/D11 -> 0.06 | I11: custo fixo | L11: =K7*J3 -> 0.22037037
A12: sacola | D12: 10 | E12: 12 | F12: 1 | I12: custo variável | L12: =G18 -> 4.9991463
A13: fita cetim | D13: 10000 | E13: 14 | F13: 430 | G13: =(F13*E13)/D13 -> 0.602 | I13: mão de obra | L13: =K8*J3 -> 0.9469697
A14: petala | D14: 50 | E14: 2 | F14: 3 | G14: =(F14*E14)/D14 -> 0.12 | I14: Custo total | L14: =SUM(L11:L13) -> 6.1664864
I15: Lucro 30% | L15: =L14*1 -> 6.1664864
D16: 1 | G16: =(F16*E16)/D16 -> 0 | I16: Valor ideal de venda | L16: =SUM(L14+L15) -> 12.332973
D17: 1 | E17: 0 | F17: 0 | G17: =(F17*E17)/D17 -> 0 | I17: VENDA
E18: Custo total de matéria-prima | G18: =SUM(G6:G13) -> 4.9991463

Sheet bombom pirâmide 
A1: FICHA TÉCNICA
A3: Produto: | B3: Mini Trufa | E3: Rendimento: | F3: 1 | H3: Tempo de preparo (min) | J3: 10
A5: Item | D5: Quant. Insumo | E5: Valo do insumo | F5: Quant. Utilizada | G5: Valor custo
A6: chocolate branco | D6: 2050 | E6: 200 | F6: 30 | G6: =(F6*E6)/D6 -> 2.9268293 | I6: Metodologia Hora Trabalhada
A7: brigadeiro Recheio | D7: 500 | E7: 17 | F7: 20 | I7: Custo fixo (R$/min) | K7: =Custos!F15 -> 0.022037037
A8: caixeta | D8: 50 | E8: 4.3 | F8: 1 | I8: Mão de obra ($/min) | K8: =Custos!L15 -> 0.09469697
A9: fundo incolor | D9: 100 | E9: 2 | F9: 1
I10: Custo total dos produto
I11: custo fixo | L11: =K7*J3 -> 0.22037037
I12: custo variável | L12: =G18 -> 2.9268293
I13: mão de obra | L13: =K8*J3 -> 0.9469697
I14: Custo total | L14: =SUM(L11:L13) -> 4.0941693
I15: Lucro 30% | L15: =L14*1 -> 4.0941693
D16: 1 | G16: =(F16*E16)/D16 -> 0 | I16: Valor ideal de venda | L16: =SUM(L14+L15) -> 8.1883387
D17: 1 | E17: 0 | F17: 0 | G17: =(F17*E17)/D17 -> 0 | I17: VENDA
E18: Custo total de matéria-prima | G18: =SUM(G6:G10) -> 2.9268293

Sheet Mini trufa
A1: FICHA TÉCNICA
A3: Produto: | B3: Mini Trufa | E3: Rendimento: | F3: 1 | H3: Tempo de preparo (min) | J3: 10
A5: Item | D5: Quant. Insumo | E5: Valo do insumo | F5: Quant. Utilizada | G5: Valor custo
A6: chocolate top Branco | D6: 2050 | E6: 63 | F6: 15 | G6: =(F6*E6)/D6 -> 0.46097561 | I6: Metodologia Hora Trabalhada
A7: brigadeiro Recheio | D7: 500 | E7: 17 | F7: 20 | G7: =(F7*E7)/D7 -> 0.68 | I7: Custo fixo (R$/min) | K7: =Custos!F15 -> 0.022037037
A8: caixeta | D8: 50 | E8: 4.3 | F8: 1 | G8: =(F8*E8)/D8 -> 0.086 | I8: Mão de obra ($/min) | K8: =Custos!L15 -> 0.09469697
A9: fundo incolor | D9: 100 | E9: 2 | F9: 1 | G9: =(F9*E9)/D9 -> 0.02
I10: Custo total dos produto
I11: custo fixo | L11: =K7*J3 -> 0.22037037
I12: custo variável | L12: =G18 -> 1.2469756
I13: mão de obra | L13: =K8*J3 -> 0.9469697
I14: Custo total | L14: =SUM(L11:L13) -> 2.4143157
I15: Lucro 30% | L15: =L14*1 -> 2.4143157
D16: 1 | G16: =(F16*E16)/D16 -> 0 | I16: Valor ideal de venda | L16: =SUM(L14+L15) -> 4.8286314
D17: 1 | E17: 0 | F17: 0 | G17: =(F17*E17)/D17 -> 0 | I17: VENDA
E18: Custo total de matéria-prima | G18: =SUM(G6:G10) -> 1.2469756

Sheet Mini trufa Cereja
A1: FICHA TÉCNICA
A3: Produto: | B3: Mini Trufa cereja cx com 9 | E3: Rendimento: | F3: 1 | H3: Tempo de preparo (min) | J3: 15
A5: Item | D5: Quant. Insumo | E5: Valo do insumo | F5: Quant. Utilizada | G5: Valor custo
A6: chocolate top | D6: 2050 | E6: 63 | F6: 144 | G6: =(F6*E6)/D6 -> 4.4253659 | I6: Metodologia Hora Trabalhada
A7: trufa | D7: 500 | E7: 24.2 | F7: 63 | G7: =(F7*E7)/D7 -> 3.0492 | I7: Custo fixo (R$/min) | K7: =Custos!F15 -> 0.022037037
A8: caixeta | D8: 50 | E8: 4.3 | F8: 9 | G8: =(F8*E8)/D8 -> 0.774 | I8: Mão de obra ($/min) | K8: =Custos!L15 -> 0.09469697
A9: fundo incolor | D9: 100 | E9: 2 | F9: 9 | G9: =(F9*E9)/D9 -> 0.18
A10: cereja | D10: 190 | E10: 20 | F10: 63 | G10: =(F10*E10)/D10 -> 6.6315789 | I10: Custo total dos produto
A11: caixa | D11: 10 | E11: 20 | F11: 1 | G11: =(F11*E11)/D11 -> 2 | I11: custo fixo | L11: =K7*J3 -> 0.33055556
I12: custo variável | L12: =G18 -> 15.060145
I13: mão de obra | L13: =K8*J3 -> 1.4204545
I14: Custo total | L14: =SUM(L11:L13) -> 16.811155
I15: Lucro 30% | L15: =L14*1 -> 16.811155
D16: 1 | G16: =(F16*E16)/D16 -> 0 | I16: Valor ideal de venda | L16: =SUM(L14+L15) -> 33.62231
D17: 1 | E17: 0 | F17: 0 | G17: =(F17*E17)/D17 -> 0 | I17: VENDA
E18: Custo total de matéria-prima | G18: =SUM(G6:G10) -> 15.060145
E20: 1,45 cada trufa

Sheet Mini Trufa Coração
A1: FICHA TÉCNICA
A3: Produto: | B3: Mini Trufa Corção | E3: Rendimento: | F3: 1 | H3: Tempo de preparo (min) | J3: 10
A5: Item | D5: Quant. Insumo | E5: Valo do insumo | F5: Quant. Utilizada | G5: Valor custo
A6: chocolate top Branco | D6: 2050 | E6: 63 | F6: 10 | G6: =(F6*E6)/D6 -> 0.30731707 | I6: Metodologia Hora Trabalhada
A7: brigadeiro Recheio | D7: 500 | E7: 17 | F7: 9 | G7: =(F7*E7)/D7 -> 0.306 | I7: Custo fixo (R$/min) | K7: =Custos!F15 -> 0.022037037
A8: caixeta | D8: 50 | E8: 4.3 | F8: 1 | G8: =(F8*E8)/D8 -> 0.086 | I8: Mão de obra ($/min) | K8: =Custos!L15 -> 0.09469697
A9: fundo incolor | D9: 100 | E9: 2 | F9: 1 | G9: =(F9*E9)/D9 -> 0.02
I10: Custo total dos produto
I11: custo fixo | L11: =K7*J3 -> 0.22037037
I12: custo variável | L12: =G18 -> 0.71931707
I13: mão de obra | L13: =K8*J3 -> 0.9469697
I14: Custo total | L14: =SUM(L11:L13) -> 1.8866571
I15: Lucro 30% | L15: =L14*1 -> 1.8866571
D16: 1 | G16: =(F16*E16)/D16 -> 0 | I16: Valor ideal de venda | L16: =SUM(L14+L15) -> 3.7733143
D17: 1 | E17: 0 | F17: 0 | G17: =(F17*E17)/D17 -> 0 | I17: VENDA
E18: Custo total de matéria-prima | G18: =SUM(G6:G10) -> 0.71931707

Sheet bombom chocolate
A1: FICHA TÉCNICA
A3: Produto: | B3: bombom chocolate | E3: Rendimento: | F3: 1 | H3: Tempo de preparo (min) | J3: 20
A5: Item | D5: Quant. Insumo | E5: Valo do insumo | F5: Quant. Utilizada | G5: Valor custo
I6: Metodologia Hora Trabalhada
A7: chocolate melken | D7: 2050 | E7: 130 | F7: 13 | G7: =(F7*E7)/D7 -> 0.82439024 | I7: Custo fixo (R$/min) | K7: =Custos!F15 -> 0.022037037
A8: caixeta | D8: 50 | E8: 4.3 | F8: 1 | G8: =(F8*E8)/D8 -> 0.086 | I8: Mão de obra ($/min) | K8: =Custos!L15 -> 0.09469697
A9: fundo incolor | D9: 100 | E9: 2 | F9: 1 | G9: =(F9*E9)/D9 -> 0.02
A10: chocolate top | D10: 2050 | E10: 70 | F10: 20 | G10: =(F10*E10)/D10 -> 0.68292683 | I10: Custo total dos produto
A11: recheio brig | D11: 500 | E11: 18 | F11: 8 | G11: =(F11*E11)/D11 -> 0.288 | I11: custo fixo | L11: =K7*J3 -> 0.44074074
I12: custo variável | L12: =G18 -> 1.9013171
I13: mão de obra | L13: =K8*J3 -> 1.8939394
I14: Custo total | L14: =SUM(L11:L13) -> 4.2359972
I15: Lucro 30% | L15: =L14*1 -> 4.2359972
D16: 1 | G16: =(F16*E16)/D16 -> 0 | I16: Valor ideal de venda | L16: =SUM(L14+L15) -> 8.4719944
D17: 1 | E17: 0 | F17: 0 | G17: =(F17*E17)/D17 -> 0 | I17: VENDA
E18: Custo total de matéria-prima | G18: =SUM(G6:G11) -> 1.9013171

Sheet Trufa Quadrado 50g
A1: FICHA TÉCNICA
A3: Produto: | B3: trufa Quadrado | E3: Rendimento: | F3: 1 | H3: Tempo de preparo (min) | J3: 5
A5: Item | D5: Quant. Insumo | E5: Valo do insumo | F5: Quant. Utilizada | G5: Valor custo
A6: chocolate top | D6: 2050 | E6: 80 | F6: 25 | G6: =(F6*E6)/D6 -> 0.97560976 | I6: Metodologia Hora Trabalhada
I7: Custo fixo (R$/min) | K7: =Custos!F15 -> 0.022037037
A8: brigadeiro | D8: 500 | E8: 18 | F8: 45 | G8: =(F8*E8)/D8 -> 1.62 | I8: Mão de obra ($/min) | K8: =Custos!L15 -> 0.09469697
A9: embalagem | D9: 100 | E9: 12 | F9: 1 | G9: =(F9*E9)/D9 -> 0.12
A10: etiqueta perso | D10: 1000 | E10: 100 | F10: 1 | G10: =(F10*E10)/D10 -> 0.1 | I10: Custo total dos produto
D11: 1 | G11: =(F11*E11)/D11 -> 0 | I11: custo fixo | L11: =K7*J3 -> 0.11018519
D12: 1 | G12: =(F12*E12)/D12 -> 0 | I12: custo variável | L12: =G18 -> 2.8156098
D13: 1 | G13: =(F13*E13)/D13 -> 0 | I13: mão de obra | L13: =K8*J3 -> 0.47348485
D14: 1 | G14: =(F14*E14)/D14 -> 0 | I14: Custo total | L14: =SUM(L11:L13) -> 3.3992798
D15: 1 | G15: =(F15*E15)/D15 -> 0 | I15: Lucro 100% | L15: =L14*1 -> 3.3992798
D16: 1 | E16: 0 | F16: 0 | G16: =(F16*E16)/D16 -> 0 | I16: Valor ideal de venda | L16: =SUM(L14:L15) -> 6.7985596
D17: 1 | E17: 0 | F17: 0 | G17: =(F17*E17)/D17 -> 0 | I17: VENDA
E18: Custo total de matéria-prima | G18: =SUM(G6:G11) -> 2.8156098
G19: =(G18/F3) -> 2.8156098
L25: Lucro 30% | O25: =L14*0.3 -> 1.0197839
L26: Lucro 50% | O26: =18.8*0.5 -> 9.4
L27: Lucro 100% | O27: =18.8*1 -> 18.8
L29: Valor ideal de venda (30%) | O29: =L14+L15 -> 6.7985596
L30: Valor ideal de venda (50%) | O30: =L14+O26 -> 12.79928
L31: Valor ideal de venda (100%) | O31: =L14+O27 -> 22.19928

Sheet PM Quadrado 50g
A1: FICHA TÉCNICA
A3: Produto: | B3: PM Quadrado | E3: Rendimento: | F3: 1 | H3: Tempo de preparo (min) | J3: 5
A5: Item | D5: Quant. Insumo | E5: Valo do insumo | F5: Quant. Utilizada | G5: Valor custo
A6: chocolate top | D6: 2050 | E6: 65 | F6: 20 | G6: =(F6*E6)/D6 -> 0.63414634 | I6: Metodologia Hora Trabalhada
A7: Massa pm | D7: 1500 | E7: 21 | F7: 17 | G7: =(F7*E7)/D7 -> 0.238 | I7: Custo fixo (R$/min) | K7: =Custos!F15 -> 0.022037037
A8: brigadeiro | D8: 500 | E8: 17 | F8: 20 | G8: =(F8*E8)/D8 -> 0.68 | I8: Mão de obra ($/min) | K8: =Custos!L15 -> 0.09469697
D10: 1 | G10: =(F10*E10)/D10 -> 0 | I10: Custo total dos produto
D11: 1 | G11: =(F11*E11)/D11 -> 0 | I11: custo fixo | L11: =K7*J3 -> 0.11018519
D12: 1 | G12: =(F12*E12)/D12 -> 0 | I12: custo variável | L12: =G18 -> 1.5521463
D13: 1 | G13: =(F13*E13)/D13 -> 0 | I13: mão de obra | L13: =K8*J3 -> 0.47348485
D14: 1 | G14: =(F14*E14)/D14 -> 0 | I14: Custo total | L14: =SUM(L11:L13) -> 2.1358164
D15: 1 | G15: =(F15*E15)/D15 -> 0 | I15: Lucro 100% | L15: =L14*1 -> 2.1358164
D16: 1 | E16: 0 | F16: 0 | G16: =(F16*E16)/D16 -> 0 | I16: Valor ideal de venda | L16: =SUM(L14:L15) -> 4.2716328
D17: 1 | E17: 0 | F17: 0 | G17: =(F17*E17)/D17 -> 0 | I17: VENDA
E18: Custo total de matéria-prima | G18: =SUM(G6:G11) -> 1.5521463
G19: =(G18/F3) -> 1.5521463
L25: Lucro 30% | O25: =L14*0.3 -> 0.64074491
L26: Lucro 50% | O26: =18.8*0.5 -> 9.4
L27: Lucro 100% | O27: =18.8*1 -> 18.8
L29: Valor ideal de venda (30%) | O29: =L14+L15 -> 4.2716328
L30: Valor ideal de venda (50%) | O30: =L14+O26 -> 11.535816
L31: Valor ideal de venda (100%) | O31: =L14+O27 -> 20.935816

Sheet pão de mel Medio
A1: FICHA TÉCNICA
A3: Produto: | B3: Pão de mel medio | E3: Rendimento: | F3: 1 | H3: Tempo de preparo (min) | J3: 5
A5: Item | D5: Quant. Insumo | E5: Valo do insumo | F5: Quant. Utilizada | G5: Valor custo
A6: chocolate top Branco | D6: 2050 | E6: 80 | F6: 30 | G6: =(F6*E6)/D6 -> 1.1707317 | I6: Metodologia Hora Trabalhada
A7: brigadeiro | D7: 500 | E7: 18 | F7: 22 | G7: =(F7*E7)/D7 -> 0.792 | I7: Custo fixo (R$/min) | K7: =Custos!F15 -> 0.022037037
A8: Massa pão de mel | D8: 1500 | E8: 21 | F8: 20 | G8: =(F8*E8)/D8 -> 0.28 | I8: Mão de obra ($/min) | K8: =Custos!L15 -> 0.09469697
A9: saquinho | D9: 100 | E9: 5 | F9: 1 | G9: =(F9*E9)/D9 -> 0.05
A10: etiqueta | D10: 1000 | E10: 100 | F10: 1 | G10: =(F10*E10)/D10 -> 0.1 | I10: Custo total dos produto
D11: 1 | G11: =(F11*E11)/D11 -> 0 | I11: custo fixo | L11: =K7*J3 -> 0.11018519
D12: 1 | G12: =(F12*E12)/D12 -> 0 | I12: custo variável | L12: =G18 -> 2.3927317
D13: 1 | G13: =(F13*E13)/D13 -> 0 | I13: mão de obra | L13: =K8*J3 -> 0.47348485
D14: 1 | G14: =(F14*E14)/D14 -> 0 | I14: Custo total | L14: =SUM(L11:L13) -> 2.9764017
D15: 1 | G15: =(F15*E15)/D15 -> 0 | I15: Lucro 100% | L15: =L14*1 -> 2.9764017
D16: 1 | E16: 0 | F16: 0 | G16: =(F16*E16)/D16 -> 0 | I16: Valor ideal de venda | L16: =SUM(L14:L15) -> 5.9528035
D17: 1 | E17: 0 | F17: 0 | G17: =(F17*E17)/D17 -> 0 | I17: VENDA
E18: Custo total de matéria-prima | G18: =SUM(G6:G10) -> 2.3927317

Sheet pão de mel Medio 3D
A1: FICHA TÉCNICA
A3: Produto: | B3: Pão de mel medio 3D | E3: Rendimento: | F3: 1 | H3: Tempo de preparo (min) | J3: 80
A5: Item | D5: Quant. Insumo | E5: Valo do insumo | F5: Quant. Utilizada | G5: Valor custo
A6: chocolate top Branco | D6: 2050 | E6: 65 | F6: 30 | G6: =(F6*E6)/D6 -> 0.95121951 | I6: Metodologia Hora Trabalhada
A7: Doce de leite | D7: 900 | E7: 16 | F7: 22 | G7: =(F7*E7)/D7 -> 0.39111111 | I7: Custo fixo (R$/min) | K7: =Custos!F15 -> 0.022037037
A8: Massa pão de mel | D8: 1500 | E8: 21 | F8: 20 | G8: =(F8*E8)/D8 -> 0.28 | I8: Mão de obra ($/min) | K8: =Custos!L15 -> 0.09469697
D9: 1 | G9: =(F9*E9)/D9 -> 0
A10: pasta de leite em pó | D10: 800 | E10: 29 | F10: 150 | G10: =(F10*E10)/D10 -> 5.4375 | I10: Custo total dos produto
D11: 1 | G11: =(F11*E11)/D11 -> 0 | I11: custo fixo | L11: =K7*J3 -> 1.762963
D12: 1 | G12: =(F12*E12)/D12 -> 0 | I12: custo variável | L12: =G18 -> 7.0598306
D13: 1 | G13: =(F13*E13)/D13 -> 0 | I13: mão de obra | L13: =K8*J3 -> 7.5757576
D14: 1 | G14: =(F14*E14)/D14 -> 0 | I14: Custo total | L14: =SUM(L11:L13) -> 16.398551
D15: 1 | G15: =(F15*E15)/D15 -> 0 | I15: Lucro 100% | L15: =L14*1 -> 16.398551
D16: 1 | E16: 0 | F16: 0 | G16: =(F16*E16)/D16 -> 0 | I16: Valor ideal de venda | L16: =SUM(L14:L15) -> 32.797102
D17: 1 | E17: 0 | F17: 0 | G17: =(F17*E17)/D17 -> 0 | I17: VENDA
E18: Custo total de matéria-prima | G18: =SUM(G6:G10) -> 7.0598306

Sheet mini pão de mel
A1: FICHA TÉCNICA
A3: Produto: | B3: Mini Pão de Mel | E3: Rendimento: | F3: 1 | H3: Tempo de preparo (min) | J3: 5
A5: Item | D5: Quant. Insumo | E5: Valo do insumo | F5: Quant. Utilizada | G5: Valor custo
A6: chocolate top Branco | D6: 2050 | E6: 65 | F6: 20 | G6: =(F6*E6)/D6 -> 0.63414634 | I6: Metodologia Hora Trabalhada
A7: Doce de leite | D7: 900 | E7: 16 | F7: 10 | G7: =(F7*E7)/D7 -> 0.17777778 | I7: Custo fixo (R$/min) | K7: =Custos!F15 -> 0.022037037
A8: Massa pão de mel | D8: 1400 | E8: 21 | F8: 10 | G8: =(F8*E8)/D8 -> 0.15 | I8: Mão de obra ($/min) | K8: =Custos!L15 -> 0.09469697
A9: etiqueta | D9: 1000 | E9: 100 | F9: 1 | G9: =(F9*E9)/D9 -> 0.1
A10: pasta leite em po | D10: 800 | E10: 29 | F10: 15 | G10: =(F10*E10)/D10 -> 0.54375 | I10: Custo total dos produto
A11: saquinho | D11: 100 | E11: 5 | F11: 1 | G11: =(F11*E11)/D11 -> 0.05 | I11: custo fixo | L11: =K7*J3 -> 0.11018519
D12: 1 | G12: =(F12*E12)/D12 -> 0 | I12: custo variável | L12: =G18 -> 1.6056741
D13: 1 | G13: =(F13*E13)/D13 -> 0 | I13: mão de obra | L13: =K8*J3 -> 0.47348485
D14: 1 | G14: =(F14*E14)/D14 -> 0 | I14: Custo total | L14: =SUM(L11:L13) -> 2.1893442
D15: 1 | G15: =(F15*E15)/D15 -> 0 | I15: Lucro 30% | L15: =L14*1 -> 2.1893442
D16: 1 | E16: 0 | F16: 0 | G16: =(F16*E16)/D16 -> 0 | I16: Valor ideal de venda | L16: =SUM(L14:L15) -> 4.3786883
D17: 1 | E17: 0 | F17: 0 | G17: =(F17*E17)/D17 -> 0 | I17: VENDA
E18: Custo total de matéria-prima | G18: =SUM(G6:G10) -> 1.6056741

Sheet Pirulito Personalizado
A1: FICHA TÉCNICA
A3: Produto: | B3: Pirulito Personalizado | E3: Rendimento: | F3: 1 | H3: Tempo de preparo (min) | J3: 45
A5: Item | D5: Quant. Insumo | E5: Valo do insumo | F5: Quant. Utilizada | G5: Valor custo
A6: chocolate Branco | D6: 2050 | E6: 130 | F6: 30 | G6: =(F6*E6)/D6 -> 1.902439 | I6: Metodologia Hora Trabalhada
A7: Palito | D7: 12 | E7: 6.4 | F7: 1 | G7: =(F7*E7)/D7 -> 0.53333333 | I7: Custo fixo (R$/min) | K7: =Custos!F15 -> 0.022037037
A8: fita | D8: 1000 | E8: 6 | F8: 22 | G8: =(F8*E8)/D8 -> 0.132 | I8: Mão de obra ($/min) | K8: =Custos!L15 -> 0.09469697
A10: pasta leite em po | D10: 800 | E10: 29 | F10: 15 | G10: =(F10*E10)/D10 -> 0.54375 | I10: Custo total dos produto
D11: 1 | G11: =(F11*E11)/D11 -> 0 | I11: custo fixo | L11: =K7*J3 -> 0.99166667
D12: 1 | G12: =(F12*E12)/D12 -> 0 | I12: custo variável | L12: =G18 -> 3.1115224
D13: 1 | G13: =(F13*E13)/D13 -> 0 | I13: mão de obra | L13: =K8*J3 -> 4.2613636
D14: 1 | G14: =(F14*E14)/D14 -> 0 | I14: Custo total | L14: =SUM(L11:L13) -> 8.3645527
D15: 1 | G15: =(F15*E15)/D15 -> 0 | I15: Lucro 30% | L15: =L14*1 -> 8.3645527
D16: 1 | E16: 0 | F16: 0 | G16: =(F16*E16)/D16 -> 0 | I16: Valor ideal de venda | L16: =SUM(L14:L15) -> 16.729105
D17: 1 | E17: 0 | F17: 0 | G17: =(F17*E17)/D17 -> 0 | I17: VENDA
E18: Custo total de matéria-prima | G18: =SUM(G6:G10) -> 3.1115224

Sheet Pirulito Simples
A1: FICHA TÉCNICA
A3: Produto: | B3: Pirulito Simples | E3: Rendimento: | F3: 1 | H3: Tempo de preparo (min) | J3: 15
A5: Item | D5: Quant. Insumo | E5: Valo do insumo | F5: Quant. Utilizada | G5: Valor custo
A6: chocolate Branco | D6: 2050 | E6: 200 | F6: 20 | G6: =(F6*E6)/D6 -> 1.9512195 | I6: Metodologia Hora Trabalhada
A7: Palito | D7: 12 | E7: 6.4 | F7: 1 | G7: =(F7*E7)/D7 -> 0.53333333 | I7: Custo fixo (R$/min) | K7: =Custos!F15 -> 0.022037037
A8: fita | D8: 1000 | E8: 6 | F8: 22 | G8: =(F8*E8)/D8 -> 0.132 | I8: Mão de obra ($/min) | K8: =Custos!L15 -> 0.09469697
A10: pasta leite em po | D10: 800 | E10: 29 | F10: 15 | G10: =(F10*E10)/D10 -> 0.54375 | I10: Custo total dos produto
D11: 1 | G11: =(F11*E11)/D11 -> 0 | I11: custo fixo | L11: =K7*J3 -> 0.33055556
D12: 1 | G12: =(F12*E12)/D12 -> 0 | I12: custo variável | L12: =G18 -> 3.1603028
D13: 1 | G13: =(F13*E13)/D13 -> 0 | I13: mão de obra | L13: =K8*J3 -> 1.4204545
D14: 1 | G14: =(F14*E14)/D14 -> 0 | I14: Custo total | L14: =SUM(L11:L13) -> 4.9113129
D15: 1 | G15: =(F15*E15)/D15 -> 0 | I15: Lucro 30% | L15: =L14*1 -> 4.9113129
D16: 1 | E16: 0 | F16: 0 | G16: =(F16*E16)/D16 -> 0 | I16: Valor ideal de venda | L16: =SUM(L14:L15) -> 9.8226259
D17: 1 | E17: 0 | F17: 0 | G17: =(F17*E17)/D17 -> 0 | I17: VENDA
E18: Custo total de matéria-prima | G18: =SUM(G6:G10) -> 3.1603028

Sheet Brigadeiro boleado (2)
A1: FICHA TÉCNICA
A3: Produto: | B3: Brigadeiro boleado grande | E3: Rendimento: | F3: 50 | H3: Tempo de preparo (min) | J3: 180
A5: Item | D5: Quant. Insumo | E5: Valo do insumo | F5: Quant. Utilizada | G5: Valor custo
A6: leite condensado | D6: 395 | E6: 7 | F6: 790 | G6: =(F6*E6)/D6 -> 14 | I6: Metodologia Hora Trabalhada
A7: creme de leite | D7: 200 | E7: 3.5 | F7: 400 | G7: =(F7*E7)/D7 -> 7 | I7: Custo fixo ($/min) | K7: =Custos!F15 -> 0.022037037
A8: chocolate em pó | D8: 1000 | E8: 40 | F8: 180 | G8: =(F8*E8)/D8 -> 7.2 | I8: Mão de obra ($/min) | K8: =Custos!L15 -> 0.09469697
A9: margarina | D9: 1000 | E9: 15 | F9: 30 | G9: =(F9*E9)/D9 -> 0.45
